Workbook

Sheet action
A1: ##var | B1: id | C1: name | D1: desc | E1: behavior | F1: foodId | G1: minCostDays | H1: maxCostDays
A2: ##comment | B2: 行动ID | C2: 卡面标题(食物/事件由明细表覆盖) | D2: 卡面描述 | E2: 行动行为(分派 handler) | F2: Food:关联具体美食 TbFood.id(1:1) | G2: 本次最小耗时(0.1天) | H2: 本次最大耗时(0.1天)
A3: ##type | B3: string | C3: string | D3: string | E3: ActionBehavior | F3: string | G3: float | H3: float
B4: act_food_gold | C4: 美食 | D4: 普通美食：主要奖励金币。 | E4: Food | F4: food_gold | G4: 0.5 | H4: 1.2
B5: act_food_fragment | C5: 美食 | D5: 普通美食：主要奖励胃部碎片。 | E5: Food | F5: food_fragment | G5: 0.5 | H5: 1.2
B6: act_food_passive | C6: 美食 | D6: 普通美食：主要奖励被动道具。 | E6: Food | F6: food_passive | G6: 0.5 | H6: 1.2
B7: act_food_active | C7: 美食 | D7: 普通美食：主要奖励主动道具。 | E7: Food | F7: food_active | G7: 0.5 | H7: 1.2
B8: act_food_dish | C8: 美食 | D8: 普通美食：主要奖励菜品。 | E8: Food | F8: food_dish | G8: 0.5 | H8: 1.2
B9: act_food_hard_gold | C9: 超级美食 | D9: 困难美食：主要奖励金币。 | E9: Food | F9: food_hard_gold | G9: 0.7 | H9: 1.5
B10: act_food_hard_fragment | C10: 超级美食 | D10: 困难美食：主要奖励胃部碎片。 | E10: Food | F10: food_hard_fragment | G10: 0.7 | H10: 1.5
B11: act_food_hard_passive | C11: 超级美食 | D11: 困难美食：主要奖励被动道具。 | E11: Food | F11: food_hard_passive | G11: 0.7 | H11: 1.5
B12: act_food_hard_active | C12: 超级美食 | D12: 困难美食：主要奖励主动道具。 | E12: Food | F12: food_hard_active | G12: 0.7 | H12: 1.5
B13: act_food_hard_dish | C13: 超级美食 | D13: 困难美食：主要奖励菜品。 | E13: Food | F13: food_hard_dish | G13: 0.7 | H13: 1.5
B14: act_event | C14: 事件 | D14: 一个待揭晓的事件。 | E14: Event | G14: 0.5 | H14: 1.5
B15: act_reward | C15: 奖励 | D15: 一份即时奖励。 | E15: Reward | G15: 1 | H15: 1.8
B16: act_shop | C16: 商店 | D16: 去食材店转转，买卖道具。 | E16: Shop | G16: 0 | H16: 0
B17: act_interest | C17: 利息 | D17: 到点自动结算利息。 | E17: Interest | G17: 0 | H17: 0
B18: act_boss | C18: 盛宴 | D18: 带有特殊机制的盛宴挑战。 | E18: Food | F18: food_boss | G18: 0 | H18: 0

Sheet large_group
A1: ##var | B1: id | C1: name | D1: ruleIds | E1: fallbackWeights | F1: smallGroupIds
A2: ##comment | B2: 大组ID | C2: 大组名 | D2: 参与的日程规则ID(逗号分隔),空=仅保底 | E2: 随机权重列表(按周配) | F2: 包含的小组ID列表→small_group.id
A3: ##type | B3: string | C3: string | D3: string | E3: list,float | F3: list,string
B4: lg_normal | C4: 普通美食大组 | E4: =_xlfn.TEXTJOIN(",",TRUE,I4:L4) -> 400,300,200,150 | F4: =_xlfn.TEXTJOIN("|",TRUE,small_group!B4:B23) -> sg_normal_1|sg_normal_2|sg_normal_3|sg_normal_4|sg_normal_5|sg_normal_6|sg_normal_7|sg_normal_8|sg_normal_9|sg_normal_10|sg_normal_11|sg_normal_12|sg_normal_13|sg_normal_14|sg_normal_15|sg_normal_16|sg_normal_17|sg_normal_18|sg_normal_19|sg_normal_20 | G4: ="" | I4: 400 | J4: 300 | K4: 200 | L4: 150
B5: lg_normalHard | C5: 普通困难美食大组 | E5: =_xlfn.TEXTJOIN(",",TRUE,I5:L5) -> 200,200,250,200 | F5: =_xlfn.TEXTJOIN("|",TRUE,small_group!B24:B103) -> sg_normalHard_1|sg_normalHard_2|sg_normalHard_3|sg_normalHard_4|sg_normalHard_5|sg_normalHard_6|sg_normalHard_7|sg_normalHard_8|sg_normalHard_9|sg_normalHard_10|sg_normalHard_11|sg_normalHard_12|sg_normalHard_13|sg_normalHard_14|sg_normalHard_15|sg_normalHard_16|sg_normalHard_17|sg_normalHard_18|sg_normalHard_19|sg_normalHard_20|sg_normalHard_21|sg_normalHard_22|sg_normalHard_23|sg_normalHard_24|sg_normalHard_25|sg_normalHard_26|sg_normalHard_27|sg_normalHard_28|sg_normalHard_29|sg_normalHard_30|sg_normalHard_31|sg_normalHard_32|sg_normalHard_33|sg_normalHard_34|sg_normalHard_35|sg_normalHard_36|sg_normalHard_37|sg_normalHard_38|sg_normalHard_39|sg_normalHard_40|sg_normalHard_41|sg_normalHard_42|sg_normalHard_43|sg_normalHard_44|sg_normalHard_45|sg_normalHard_46|sg_normalHard_47|sg_normalHard_48|sg_normalHard_49|sg_normalHard_50|sg_normalHard_51|sg_normalHard_52|sg_normalHard_53|sg_normalHard_54|sg_normalHard_55|sg_normalHard_56|sg_normalHard_57|sg_normalHard_58|sg_normalHard_59|sg_normalHard_60|sg_normalHard_61|sg_normalHard_62|sg_normalHard_63|sg_normalHard_64|sg_normalHard_65|sg_normalHard_66|sg_normalHard_67|sg_normalHard_68|sg_normalHard_69|sg_normalHard_70|sg_normalHard_71|sg_normalHard_72|sg_normalHard_73|sg_normalHard_74|sg_normalHard_75|sg_normalHard_76|sg_normalHard_77|sg_normalHard_78|sg_normalHard_79|sg_normalHard_80 | G5: ="" | I5: 200 | J5: 200 | K5: 250 | L5: 200
B6: lg_hard | C6: 困难美食大组 | E6: =_xlfn.TEXTJOIN(",",TRUE,I6:L6) -> 0,50,100,200 | F6: =_xlfn.TEXTJOIN("|",TRUE,small_group!B104:B123) -> sg_hard_1|sg_hard_2|sg_hard_3|sg_hard_4|sg_hard_5|sg_hard_6|sg_hard_7|sg_hard_8|sg_hard_9|sg_hard_10|sg_hard_11|sg_hard_12|sg_hard_13|sg_hard_14|sg_hard_15|sg_hard_16|sg_hard_17|sg_hard_18|sg_hard_19|sg_hard_20 | G6: ="" | I6: 0 | J6: 50 | K6: 100 | L6: 200
B7: lg_event | C7: 事件大组 | D7: rule_event_opening | E7: =_xlfn.TEXTJOIN(",",TRUE,I7:L7) -> 100,100,100,100 | F7: sg_event_1 | G7: ="" | I7: 100 | J7: 100 | K7: 100 | L7: 100
B8: lg_reward | C8: 奖励大组 | D8: rule_reward_early,rule_reward_mid | E8: =_xlfn.TEXTJOIN(",",TRUE,I8:L8) -> 50,50,50,50 | F8: sg_reward_1 | G8: ="" | I8: 50 | J8: 50 | K8: 50 | L8: 50
B9: lg_normalEvent | C9: 普通事件大组 | E9: =_xlfn.TEXTJOIN(",",TRUE,I9:L9) -> 150,150,100,100 | F9: =_xlfn.TEXTJOIN("|",TRUE,small_group!B126:B140) -> sg_normalEvent_1|sg_normalEvent_2|sg_normalEvent_3|sg_normalEvent_4|sg_normalEvent_5|sg_normalEvent_6|sg_normalEvent_7|sg_normalEvent_8|sg_normalEvent_9|sg_normalEvent_10|sg_normalEvent_11|sg_normalEvent_12|sg_normalEvent_13|sg_normalEvent_14|sg_normalEvent_15 | G9: ="" | I9: 150 | J9: 150 | K9: 100 | L9: 100
B10: lg_normalHardEvent | C10: 普通困难事件大组 | E10: =_xlfn.TEXTJOIN(",",TRUE,I10:L10) -> 100,100,100,100 | F10: =_xlfn.TEXTJOIN("|",TRUE,small_group!B141:B150) -> sg_normalHardEvent_1|sg_normalHardEvent_2|sg_normalHardEvent_3|sg_normalHardEvent_4|sg_normalHardEvent_5|sg_normalHardEvent_6|sg_normalHardEvent_7|sg_normalHardEvent_8|sg_normalHardEvent_9|sg_normalHardEvent_10 | G10: ="" | I10: 100 | J10: 100 | K10: 100 | L10: 100
B11: lg_hardEvent | C11: 困难事件大组 | E11: =_xlfn.TEXTJOIN(",",TRUE,I11:L11) -> 0,50,100,100 | F11: =_xlfn.TEXTJOIN("|",TRUE,small_group!B151:B165) -> sg_hardEvent_1|sg_hardEvent_2|sg_hardEvent_3|sg_hardEvent_4|sg_hardEvent_5|sg_hardEvent_6|sg_hardEvent_7|sg_hardEvent_8|sg_hardEvent_9|sg_hardEvent_10|sg_hardEvent_11|sg_hardEvent_12|sg_hardEvent_13|sg_hardEvent_14|sg_hardEvent_15 | G11: ="" | I11: 0 | J11: 50 | K11: 100 | L11: 100
B12: lg_debug | C12: 调试大组 | D12: rule_debug_first | E12: =_xlfn.TEXTJOIN(",",TRUE,I12:L12) -> 0,0,0,0 | F12: mg_debug | G12: ="" | I12: 0 | J12: 0 | K12: 0 | L12: 0

Sheet small_group
A1: ##var | B1: id | C1: name | D1: weight | E1: actionIds
A2: ##comment | B2: 小组ID | C2: 小组名(调试用) | D2: 被大组选中的权重 | E2: 小组内固定行动ID列表→action.id
A3: ##type | B3: string | C3: string | D3: float | E3: list,string
B4: sg_normal_1 | C4: 普通1 | D4: 100 | E4: act_food_gold|act_food_fragment|act_food_passive
B5: sg_normal_2 | C5: 普通2 | D5: 100 | E5: act_food_gold|act_food_fragment|act_food_active | R5: sg_normalEvent_15
B6: sg_normal_3 | C6: 普通3 | D6: 100 | E6: act_food_gold|act_food_fragment|act_food_dish | R6: sg_normalHardEvent_1
B7: sg_normal_4 | C7: 普通4 | D7: 100 | E7: act_food_gold|act_food_passive|act_food_active | R7: sg_hardEvent_1
B8: sg_normal_5 | C8: 普通5 | D8: 100 | E8: act_food_gold|act_food_passive|act_food_dish
B9: sg_normal_6 | C9: 普通6 | D9: 100 | E9: act_food_gold|act_food_active|act_food_dish
B10: sg_normal_7 | C10: 普通7 | D10: 100 | E10: act_food_fragment|act_food_passive|act_food_active
B11: sg_normal_8 | C11: 普通8 | D11: 100 | E11: act_food_fragment|act_food_passive|act_food_dish
B12: sg_normal_9 | C12: 普通9 | D12: 100 | E12: act_food_fragment|act_food_active|act_food_dish
B13: sg_normal_10 | C13: 普通10 | D13: 100 | E13: act_food_passive|act_food_active|act_food_dish
B14: sg_normal_11 | C14: 普通11 | D14: 100 | E14: act_food_gold|act_food_fragment | L14: lg_normal | M14: 普通美食大组
B15: sg_normal_12 | C15: 普通12 | D15: 100 | E15: act_food_gold|act_food_passive | L15: lg_normalHard | M15: 普通困难美食大组
B16: sg_normal_13 | C16: 普通13 | D16: 100 | E16: act_food_gold|act_food_active | L16: lg_hard | M16: 困难美食大组
B17: sg_normal_14 | C17: 普通14 | D17: 100 | E17: act_food_gold|act_food_dish | L17: lg_event | M17: 事件大组
B18: sg_normal_15 | C18: 普通15 | D18: 100 | E18: act_food_fragment|act_food_passive | L18: lg_reward | M18: 奖励大组
B19: sg_normal_16 | C19: 普通16 | D19: 100 | E19: act_food_fragment|act_food_active | L19: lg_normalEvent | M19: 普通事件大组
B20: sg_normal_17 | C20: 普通17 | D20: 100 | E20: act_food_fragment|act_food_dish | L20: lg_normalHardEvent | M20: 普通困难混合大组
B21: sg_normal_18 | C21: 普通18 | D21: 100 | E21: act_food_passive|act_food_active | L21: lg_hardEvent | M21: 困难事件大组 | R21: act_food_gold | S21: act_food_fragment | T21: act_food_passive
B22: sg_normal_19 | C22: 普通19 | D22: 100 | E22: act_food_passive|act_food_dish | L22: lg_debug | M22: 调试大组 | R22: act_food_gold | S22: act_food_fragment | T22: act_food_active
B23: sg_normal_20 | C23: 普通20 | D23: 100 | E23: act_food_active|act_food_dish | R23: act_food_gold | S23: act_food_fragment | T23: act_food_dish
B24: sg_normalHard_1 | C24: 普通困难1 | D24: 100 | E24: act_food_hard_gold|act_food_fragment|act_food_passive | R24: act_food_gold | S24: act_food_passive | T24: act_food_active
B25: sg_normalHard_2 | C25: 普通困难2 | D25: 100 | E25: act_food_hard_gold|act_food_fragment|act_food_active | R25: act_food_gold | S25: act_food_passive | T25: act_food_dish
B26: sg_normalHard_3 | C26: 普通困难3 | D26: 100 | E26: act_food_hard_gold|act_food_fragment|act_food_dish | R26: act_food_gold | S26: act_food_active | T26: act_food_dish
B27: sg_normalHard_4 | C27: 普通困难4 | D27: 100 | E27: act_food_hard_gold|act_food_passive|act_food_active | R27: act_food_fragment | S27: act_food_passive | T27: act_food_active
B28: sg_normalHard_5 | C28: 普通困难5 | D28: 100 | E28: act_food_hard_gold|act_food_passive|act_food_dish | R28: act_food_fragment | S28: act_food_passive | T28: act_food_dish
B29: sg_normalHard_6 | C29: 普通困难6 | D29: 100 | E29: act_food_hard_gold|act_food_active|act_food_dish | R29: act_food_fragment | S29: act_food_active | T29: act_food_dish
B30: sg_normalHard_7 | C30: 普通困难7 | D30: 100 | E30: act_food_hard_fragment|act_food_passive|act_food_active | R30: act_food_passive | S30: act_food_active | T30: act_food_dish
B31: sg_normalHard_8 | C31: 普通困难8 | D31: 100 | E31: act_food_hard_fragment|act_food_passive|act_food_dish | R31: act_food_gold | S31: act_food_fragment
B32: sg_normalHard_9 | C32: 普通困难9 | D32: 100 | E32: act_food_hard_fragment|act_food_active|act_food_dish | R32: act_food_gold | S32: act_food_passive
B33: sg_normalHard_10 | C33: 普通困难10 | D33: 100 | E33: act_food_hard_passive|act_food_active|act_food_dish | R33: act_food_gold | S33: act_food_active
B34: sg_normalHard_11 | C34: 普通困难11 | D34: 100 | E34: act_food_hard_gold|act_food_fragment | R34: act_food_gold | S34: act_food_dish
B35: sg_normalHard_12 | C35: 普通困难12 | D35: 100 | E35: act_food_hard_gold|act_food_passive | R35: act_food_fragment | S35: act_food_passive
B36: sg_normalHard_13 | C36: 普通困难13 | D36: 100 | E36: act_food_hard_gold|act_food_active | R36: act_food_fragment | S36: act_food_active
B37: sg_normalHard_14 | C37: 普通困难14 | D37: 100 | E37: act_food_hard_gold|act_food_dish | L37: act_food_gold | R37: act_food_fragment | S37: act_food_dish
B38: sg_normalHard_15 | C38: 普通困难15 | D38: 100 | E38: act_food_hard_fragment|act_food_passive | L38: act_food_fragment | R38: act_food_passive | S38: act_food_active
B39: sg_normalHard_16 | C39: 普通困难16 | D39: 100 | E39: act_food_hard_fragment|act_food_active | L39: act_food_passive | R39: act_food_passive | S39: act_food_dish
B40: sg_normalHard_17 | C40: 普通困难17 | D40: 100 | E40: act_food_hard_fragment|act_food_dish | L40: act_food_active | R40: act_food_active | S40: act_food_dish
...

Sheet action_schedule_rule
A1: ##var | B1: id | C1: priority | D1: minRunStep | E1: maxRunStep | F1: minCount | G1: maxCount | H1: preconditions
A2: ##comment | B2: 规则ID(大组用 ruleIds 引用它) | C2: 优先级,越大越先填充 | D2: 整局行动序号窗口起点,1-based | E2: 窗口终点,含 | F2: 窗口内至少出现次数 | G2: 窗口内最多出现次数 | H2: 规则前置条件
A3: ##type | B3: string | C3: int | D3: int | E3: int | F3: int | G3: int | H3: string
B4: rule_reward_early | C4: 100 | D4: 3 | E4: 6 | F4: 1 | G4: 1
B5: rule_reward_mid | C5: 95 | D5: 10 | E5: 12 | F5: 1 | G5: 1
B6: rule_event_opening | C6: 80 | D6: 2 | E6: 8 | F6: 1 | G6: 1
B7: rule_debug_first | C7: 1000 | D7: 1 | E7: 1 | F7: 1 | G7: 1
