Workbook

Sheet dish_base
A1: ##var | B1: id | C1: name | D1: deliciousness | E1: allowRotate | F1: skills | G1: category | H1: countAs | I1: *shapeRows | K1: =""
A2: ##comment | B2: 菜品基础ID | C2: 菜品名称 | D2: 基础美味度 | E2: 是否允许旋转摆放 | F2: 技能ID列表(| 分隔) | G2: 菜品分类(如cake;空=无) | H2: 视为食物数(默认1) | I2: 菜品形状行列表 | K2: ="" | L2: 策划备注
A3: ##type | B3: string | C3: string | D3: int | E3: bool | F3: string | G3: string | H3: int | I3: list,string | K3: ="" | L3: 对应子技能
B4: cookie | C4: 曲奇 | D4: 10 | E4: false | F4: sk_cookie | H4: 1 | I4: X | K4: ="" | L4: =IFERROR(VLOOKUP(F4,skill!$B$4:$D$50,3,FALSE),"") -> ss_edge_multflat_v3 | M4: ss_edge_multflat_v3 | O4: =IFERROR(VLOOKUP(M4,sub_skill!$B:$R,15,FALSE),"") -> 处在棋盘边缘时，{ascopes}倍率 {0}。 | P4: =IFERROR(VLOOKUP(N4,sub_skill!$B:$R,15,FALSE),"")
B5: macaron | C5: 马卡龙 | D5: 8 | E5: false | F5: sk_macaron | H5: 1 | I5: X | K5: ="" | L5: =IFERROR(VLOOKUP(F5,skill!$B$4:$D$50,3,FALSE),"") -> ss_flat_per_dish_adj_v8|ss_transfer_row_n1 | M5: ss_flat_per_dish_adj_v8 | N5: ss_transfer_row_n1 | O5: =IFERROR(VLOOKUP(M5,sub_skill!$B:$R,15,FALSE),"") -> {cscope}每有 1 {unit}食物，{ascopes}分数 {0}。 | P5: =IFERROR(VLOOKUP(N5,sub_skill!$B:$R,15,FALSE),"") -> 甜蜜传递至{ascopes}食物
B6: pudding | C6: 布丁 | D6: 30 | E6: false | F6: sk_pudding | H6: 1 | I6: X | K6: ="" | L6: =IFERROR(VLOOKUP(F6,skill!$B$4:$D$50,3,FALSE),"") -> ss_flat_per_empty_adj_vm2 | M6: ss_flat_per_empty_adj_vm2 | O6: =IFERROR(VLOOKUP(M6,sub_skill!$B:$R,15,FALSE),"") -> {cscope}每有 1 个空格，{ascopes}分数 {0}。 | P6: =IFERROR(VLOOKUP(N6,sub_skill!$B:$R,15,FALSE),"")
B7: puff | C7: 泡芙 | D7: 8 | E7: false | F7: sk_puff | H7: 1 | I7: X | K7: ="" | L7: =IFERROR(VLOOKUP(F7,skill!$B$4:$D$50,3,FALSE),"") -> ss_layer_per_dish_adj_v2 | M7: ss_layer_per_dish_adj_v2 | O7: =IFERROR(VLOOKUP(M7,sub_skill!$B:$R,15,FALSE),"") -> {cscope}每有 1 {unit}食物，欢乐蛋糕 {0} 层。 | P7: =IFERROR(VLOOKUP(N7,sub_skill!$B:$R,15,FALSE),"")
B8: eggtart | C8: 蛋挞 | D8: 6 | E8: false | F8: sk_eggtart | H8: 1 | I8: X | K8: ="" | L8: =IFERROR(VLOOKUP(F8,skill!$B$4:$D$50,3,FALSE),"") -> ss_flat_per_run_v6 | M8: ss_flat_per_run_v6 | O8: =IFERROR(VLOOKUP(M8,sub_skill!$B:$R,15,FALSE),"") -> 结算时，{ascopes}分数永久 {0}。 | P8: =IFERROR(VLOOKUP(N8,sub_skill!$B:$R,15,FALSE),"")
B9: mochi | C9: 麻薯 | D9: 10 | E9: false | F9: sk_mochi | H9: 1 | I9: X | K9: ="" | L9: =IFERROR(VLOOKUP(F9,skill!$B$4:$D$50,3,FALSE),"") -> ss_multflat_per_dish_col_v1 | M9: ss_multflat_per_dish_col_v1 | O9: =IFERROR(VLOOKUP(M9,sub_skill!$B:$R,15,FALSE),"") -> {cscope}每有 1 {unit}食物，{ascopes}倍率 {0}。 | P9: =IFERROR(VLOOKUP(N9,sub_skill!$B:$R,15,FALSE),"")
B10: daifuku | C10: 大福 | D10: 6 | E10: false | F10: sk_daifuku | H10: 1 | I10: X | K10: ="" | L10: =IFERROR(VLOOKUP(F10,skill!$B$4:$D$50,3,FALSE),"") -> ss_flat_per_dish_row_v10 | M10: ss_flat_per_dish_row_v10 | O10: =IFERROR(VLOOKUP(M10,sub_skill!$B:$R,15,FALSE),"") -> {cscope}每有 1 {unit}食物，{ascopes}分数 {0}。 | P10: =IFERROR(VLOOKUP(N10,sub_skill!$B:$R,15,FALSE),"")
B11: choco_candy | C11: 巧克力糖 | D11: 10 | E11: false | F11: sk_choco_candy | H11: 1 | I11: X | K11: ="" | L11: =IFERROR(VLOOKUP(F11,skill!$B$4:$D$50,3,FALSE),"") -> ss_permflat_per_tag_v5 | M11: ss_permflat_per_tag_v5 | O11: =IFERROR(VLOOKUP(M11,sub_skill!$B:$R,15,FALSE),"") -> 结算每有1个技能，{ascopes}分数永久 {0}。 | P11: =IFERROR(VLOOKUP(N11,sub_skill!$B:$R,15,FALSE),"")
B12: jelly | C12: 果冻 | D12: 4 | E12: false | F12: sk_jelly | H12: 1 | I12: X | K12: ="" | L12: =IFERROR(VLOOKUP(F12,skill!$B$4:$D$50,3,FALSE),"") -> ss_multflat_per_dish_all_adj_v0p2 | M12: ss_multflat_per_dish_all_adj_v0p2 | O12: =IFERROR(VLOOKUP(M12,sub_skill!$B:$R,15,FALSE),"") -> {cscope}每有 1 {unit}食物，{ascopes}倍率 {0}。 | P12: =IFERROR(VLOOKUP(N12,sub_skill!$B:$R,15,FALSE),"")
B13: cream_cell | C13: 奶油小格 | D13: 10 | E13: false | F13: sk_cream_cell | H13: 1 | I13: X | K13: ="" | L13: =IFERROR(VLOOKUP(F13,skill!$B$4:$D$50,3,FALSE),"") -> ss_layer_add_v5 | M13: ss_layer_add_v5 | O13: =IFERROR(VLOOKUP(M13,sub_skill!$B:$R,15,FALSE),"") -> 欢乐蛋糕 {0} 层。 | P13: =IFERROR(VLOOKUP(N13,sub_skill!$B:$R,15,FALSE),"")
B14: sugarbean | C14: 糖豆 | D14: 10 | E14: false | F14: sk_sugarbean | H14: 1 | I14: X | K14: ="" | L14: =IFERROR(VLOOKUP(F14,skill!$B$4:$D$50,3,FALSE),"") -> ss_extra_settle_v1|ss_transfer_all_n1 | M14: ss_extra_settle_v1 | N14: ss_transfer_all_n1 | O14: =IFERROR(VLOOKUP(M14,sub_skill!$B:$R,15,FALSE),"") -> 技能额外结算 {0} 次。 | P14: =IFERROR(VLOOKUP(N14,sub_skill!$B:$R,15,FALSE),"") -> 甜蜜传递至{ascopes}食物
B15: gold_choco | C15: 金巧克力 | D15: 6 | E15: false | F15: sk_gold_choco | H15: 1 | I15: X | K15: ="" | L15: =IFERROR(VLOOKUP(F15,skill!$B$4:$D$50,3,FALSE),"") -> ss_grant_gold_filled_adj_v30 | M15: ss_grant_gold_filled_adj_v30 | O15: =IFERROR(VLOOKUP(M15,sub_skill!$B:$R,15,FALSE),"") -> 若{cscope}被填满，获得 {0} 金币。 | P15: =IFERROR(VLOOKUP(N15,sub_skill!$B:$R,15,FALSE),"")
B16: milk_slice | C16: 奶片 | D16: 8 | E16: false | F16: sk_milk_slice | H16: 1 | I16: X | K16: ="" | L16: =IFERROR(VLOOKUP(F16,skill!$B$4:$D$50,3,FALSE),"") -> ss_layer_filled_row_v10 | M16: ss_layer_filled_row_v10 | O16: =IFERROR(VLOOKUP(M16,sub_skill!$B:$R,15,FALSE),"") -> 若{cscope}被填满，欢乐蛋糕 {0} 层。 | P16: =IFERROR(VLOOKUP(N16,sub_skill!$B:$R,15,FALSE),"")
B17: sundae | C17: 圣代 | D17: 20 | E17: false | F17: sk_sundae | H17: 1 | I17: XX | K17: ="" | L17: =IFERROR(VLOOKUP(F17,skill!$B$4:$D$50,3,FALSE),"") -> ss_multflat_per_dish_row_v2|ss_count_as_base_v1 | M17: ss_multflat_per_dish_row_v2 | N17: ss_count_as_base_v1 | O17: =IFERROR(VLOOKUP(M17,sub_skill!$B:$R,15,FALSE),"") -> {cscope}每有 1 {unit}食物，{ascopes}倍率 {0}。 | P17: =IFERROR(VLOOKUP(N17,sub_skill!$B:$R,15,FALSE),"") -> {ascopes}视为 {countas} 个食物。
B18: cone | C18: 甜筒 | D18: 20 | E18: false | F18: sk_cone | H18: 1 | I18: X | K18: ="" | L18: =IFERROR(VLOOKUP(F18,skill!$B$4:$D$50,3,FALSE),"") -> ss_layer_add_v10|ss_temp_copy_v1 | M18: ss_layer_add_v10 | N18: ss_temp_copy_v1 | O18: =IFERROR(VLOOKUP(M18,sub_skill!$B:$R,15,FALSE),"") -> 欢乐蛋糕 {0} 层。 | P18: =IFERROR(VLOOKUP(N18,sub_skill!$B:$R,15,FALSE),"") -> 复制本菜品至空格中。
I19: X | K19: ="" | L19: =IFERROR(VLOOKUP(F19,skill!$B$4:$D$50,3,FALSE),"") | O19: =IFERROR(VLOOKUP(M19,sub_skill!$B:$R,15,FALSE),"") | P19: =IFERROR(VLOOKUP(N19,sub_skill!$B:$R,15,FALSE),"")
B20: lollipop | C20: 棒棒糖 | D20: 10 | E20: false | F20: sk_lollipop | H20: 1 | I20: XX | K20: ="" | L20: =IFERROR(VLOOKUP(F20,skill!$B$4:$D$50,3,FALSE),"") -> ss_shape_mult_adj_v1p5|ss_transfer_col_n2 | M20: ss_shape_mult_adj_v1p5 | N20: ss_transfer_col_n2 | O20: =IFERROR(VLOOKUP(M20,sub_skill!$B:$R,15,FALSE),"") -> {cscope}有占 1 格的食物时，{ascopes}倍率 ×{0}。 | P20: =IFERROR(VLOOKUP(N20,sub_skill!$B:$R,15,FALSE),"") -> 甜蜜传递至{ascopes}食物
B21: gummy | C21: 软糖 | D21: 8 | E21: false | F21: sk_gummy | H21: 1 | I21: XX | K21: ="" | L21: =IFERROR(VLOOKUP(F21,skill!$B$4:$D$50,3,FALSE),"") -> ss_mult_per_dish_adj_v1p2|ss_transfer_adj_n2 | M21: ss_mult_per_dish_adj_v1p2 | N21: ss_transfer_adj_n2 | O21: =IFERROR(VLOOKUP(M21,sub_skill!$B:$R,15,FALSE),"") -> {cscope}每有 1 {unit}食物，{ascopes}倍率 ×{0}。 | P21: =IFERROR(VLOOKUP(N21,sub_skill!$B:$R,15,FALSE),"") -> 甜蜜传递至{ascopes}食物
B22: cupcake | C22: 杯子蛋糕 | D22: 14 | E22: false | F22: sk_cupcake | G22: cake | H22: 1 | I22: XX | K22: ="" | L22: =IFERROR(VLOOKUP(F22,skill!$B$4:$D$50,3,FALSE),"") -> ss_copy_skill_adj_v1|ss_layer_per_tag_v6 | M22: ss_copy_skill_adj_v1 | N22: ss_layer_per_tag_v6 | O22: =IFERROR(VLOOKUP(M22,sub_skill!$B:$R,15,FALSE),"") -> 复制{ascope}食物的 {0} 个技能。 | P22: =IFERROR(VLOOKUP(N22,sub_skill!$B:$R,15,FALSE),"") -> 每有 1 个技能，欢乐蛋糕 {0} 层。
B23: mousse | C23: 慕斯蛋糕 | D23: 16 | E23: false | F23: sk_mousse | G23: cake | H23: 1 | I23: X | K23: ="" | L23: =IFERROR(VLOOKUP(F23,skill!$B$4:$D$50,3,FALSE),"") -> ss_mult_v1p5|ss_extra_settle_v1 | M23: ss_mult_v1p5 | N23: ss_extra_settle_v1 | O23: =IFERROR(VLOOKUP(M23,sub_skill!$B:$R,15,FALSE),"") -> {ascopes}倍率 ×{0}。 | P23: =IFERROR(VLOOKUP(N23,sub_skill!$B:$R,15,FALSE),"") -> 技能额外结算 {0} 次。
I24: X | K24: ="" | L24: =IFERROR(VLOOKUP(F24,skill!$B$4:$D$50,3,FALSE),"") | O24: =IFERROR(VLOOKUP(M24,sub_skill!$B:$R,15,FALSE),"") | P24: =IFERROR(VLOOKUP(N24,sub_skill!$B:$R,15,FALSE),"")
B25: toffee | C25: 太妃糖 | D25: 15 | E25: false | F25: sk_toffee | H25: 1 | I25: X | K25: ="" | L25: =IFERROR(VLOOKUP(F25,skill!$B$4:$D$50,3,FALSE),"") -> ss_perm_flat_v10|ss_transfer_all_n2 | M25: ss_perm_flat_v10 | N25: ss_transfer_all_n2 | O25: =IFERROR(VLOOKUP(M25,sub_skill!$B:$R,15,FALSE),"") -> {ascopes}分数永久 {0}。 | P25: =IFERROR(VLOOKUP(N25,sub_skill!$B:$R,15,FALSE),"") -> 甜蜜传递至{ascopes}食物
I26: X | K26: ="" | L26: =IFERROR(VLOOKUP(F26,skill!$B$4:$D$50,3,FALSE),"") | O26: =IFERROR(VLOOKUP(M26,sub_skill!$B:$R,15,FALSE),"") | P26: =IFERROR(VLOOKUP(N26,sub_skill!$B:$R,15,FALSE),"")
B27: nougat | C27: 牛轧糖 | D27: 20 | E27: false | F27: sk_nougat | H27: 1 | I27: X | K27: ="" | L27: =IFERROR(VLOOKUP(F27,skill!$B$4:$D$50,3,FALSE),"") -> ss_extra_settle_v1|ss_transfer_adj_n2 | M27: ss_extra_settle_v1 | N27: ss_transfer_adj_n2 | O27: =IFERROR(VLOOKUP(M27,sub_skill!$B:$R,15,FALSE),"") -> 技能额外结算 {0} 次。 | P27: =IFERROR(VLOOKUP(N27,sub_skill!$B:$R,15,FALSE),"") -> 甜蜜传递至{ascopes}食物
I28: X | K28: ="" | L28: =IFERROR(VLOOKUP(F28,skill!$B$4:$D$50,3,FALSE),"") | O28: =IFERROR(VLOOKUP(M28,sub_skill!$B:$R,15,FALSE),"") | P28: =IFERROR(VLOOKUP(N28,sub_skill!$B:$R,15,FALSE),"")
B29: eggroll | C29: 蛋卷 | D29: 30 | E29: false | F29: sk_eggroll | H29: 1 | I29: XXX | K29: ="" | L29: =IFERROR(VLOOKUP(F29,skill!$B$4:$D$50,3,FALSE),"") -> ss_multflat_per_dish_all_v0p2|ss_count_as_base_v3 | M29: ss_multflat_per_dish_all_v0p2 | N29: ss_count_as_base_v3 | O29: =IFERROR(VLOOKUP(M29,sub_skill!$B:$R,15,FALSE),"") -> {cscope}每有 1 {unit}食物，{ascopes}倍率 {0}。 | P29: =IFERROR(VLOOKUP(N29,sub_skill!$B:$R,15,FALSE),"") -> {ascopes}视为 {countas} 个食物。
B30: choco_bar | C30: 巧克力棒 | D30: 40 | E30: false | F30: sk_choco_bar | H30: 1 | I30: XXX | K30: ="" | L30: =IFERROR(VLOOKUP(F30,skill!$B$4:$D$50,3,FALSE),"") -> ss_multflat_adj_v5|ss_transfer_all_n3 | M30: ss_multflat_adj_v5 | N30: ss_transfer_all_n3 | O30: =IFERROR(VLOOKUP(M30,sub_skill!$B:$R,15,FALSE),"") -> {ascopes}倍率 {0}。 | P30: =IFERROR(VLOOKUP(N30,sub_skill!$B:$R,15,FALSE),"") -> 甜蜜传递至{ascopes}食物
B31: eclair | C31: 闪电泡芙 | D31: 30 | E31: false | F31: sk_eclair | H31: 1 | I31: X | K31: ="" | L31: =IFERROR(VLOOKUP(F31,skill!$B$4:$D$50,3,FALSE),"") -> ss_consume_layer_v10|ss_multflat_v5 | M31: ss_consume_layer_v10 | N31: ss_multflat_v5 | O31: =IFERROR(VLOOKUP(M31,sub_skill!$B:$R,15,FALSE),"") -> 消耗 {0} 层欢乐蛋糕。 | P31: =IFERROR(VLOOKUP(N31,sub_skill!$B:$R,15,FALSE),"") -> {ascopes}倍率 {0}。
I32: X | K32: ="" | L32: =IFERROR(VLOOKUP(F32,skill!$B$4:$D$50,3,FALSE),"") | O32: =IFERROR(VLOOKUP(M32,sub_skill!$B:$R,15,FALSE),"") | P32: =IFERROR(VLOOKUP(N32,sub_skill!$B:$R,15,FALSE),"")
I33: X | K33: ="" | L33: =IFERROR(VLOOKUP(F33,skill!$B$4:$D$50,3,FALSE),"") | O33: =IFERROR(VLOOKUP(M33,sub_skill!$B:$R,15,FALSE),"") | P33: =IFERROR(VLOOKUP(N33,sub_skill!$B:$R,15,FALSE),"")
B34: tanghulu | C34: 糖葫芦 | D34: 20 | E34: false | F34: sk_tanghulu | H34: 1 | I34: X | K34: ="" | L34: =IFERROR(VLOOKUP(F34,skill!$B$4:$D$50,3,FALSE),"") -> ss_multflat_col_v3|ss_transfer_row_n3 | M34: ss_multflat_col_v3 | N34: ss_transfer_row_n3 | O34: =IFERROR(VLOOKUP(M34,sub_skill!$B:$R,15,FALSE),"") -> {ascopes}倍率 {0}。 | P34: =IFERROR(VLOOKUP(N34,sub_skill!$B:$R,15,FALSE),"") -> 甜蜜传递至{ascopes}食物
I35: X | K35: ="" | L35: =IFERROR(VLOOKUP(F35,skill!$B$4:$D$50,3,FALSE),"") | O35: =IFERROR(VLOOKUP(M35,sub_skill!$B:$R,15,FALSE),"") | P35: =IFERROR(VLOOKUP(N35,sub_skill!$B:$R,15,FALSE),"")
I36: X | K36: ="" | L36: =IFERROR(VLOOKUP(F36,skill!$B$4:$D$50,3,FALSE),"") | O36: =IFERROR(VLOOKUP(M36,sub_skill!$B:$R,15,FALSE),"") | P36: =IFERROR(VLOOKUP(N36,sub_skill!$B:$R,15,FALSE),"")
B37: souffle | C37: 舒芙蕾 | D37: 30 | E37: false | F37: sk_souffle | H37: 1 | I37: XX | K37: ="" | L37: =IFERROR(VLOOKUP(F37,skill!$B$4:$D$50,3,FALSE),"") -> ss_layer_mult_v1p5 | M37: ss_layer_mult_v1p5 | O37: =IFERROR(VLOOKUP(M37,sub_skill!$B:$R,15,FALSE),"") -> 欢乐蛋糕 ×{0} 层，至少 +{floor} 层。 | P37: =IFERROR(VLOOKUP(N37,sub_skill!$B:$R,15,FALSE),"")
I38: XX | K38: ="" | L38: =IFERROR(VLOOKUP(F38,skill!$B$4:$D$50,3,FALSE),"") | O38: =IFERROR(VLOOKUP(M38,sub_skill!$B:$R,15,FALSE),"") | P38: =IFERROR(VLOOKUP(N38,sub_skill!$B:$R,15,FALSE),"")
B39: taosu | C39: 桃酥 | D39: 20 | E39: false | F39: sk_taosu | H39: 1 | I39: XX | K39: ="" | L39: =IFERROR(VLOOKUP(F39,skill!$B$4:$D$50,3,FALSE),"") -> ss_mult_tier_dishcount_row_row | M39: ss_mult_tier_dishcount_row_row | O39: =IFERROR(VLOOKUP(M39,sub_skill!$B:$R,15,FALSE),"") -> {cscope}食物达 {tiers} 个时，{ascopes}倍率 ×{tiervals}。 | P39: =IFERROR(VLOOKUP(N39,sub_skill!$B:$R,15,FALSE),"")
I40: XX | K40: ="" | L40: =IFERROR(VLOOKUP(F40,skill!$B$4:$D$50,3,FALSE),"") | O40: =IFERROR(VLOOKUP(M40,sub_skill!$B:$R,15,FALSE),"") | P40: =IFERROR(VLOOKUP(N40,sub_skill!$B:$R,15,FALSE),"")
...

Sheet dish_variant
A1: ##var | B1: id | C1: baseId | D1: flavorId | E1: baseWeight | F1: price | G1: hiddenRange | H1: rotation
A2: ##comment | B2: 菜品变体ID | C2: 引用的菜品基础ID | D2: 风味标签ID(可空,单槽) | E2: 随机基础权重 | F2: 商店价格 | G2: 出现隐藏分区间(单元格: min,max) | H2: 固定旋转朝向(整格四向)
A3: ##type | B3: string | C3: string | D3: string | E3: float | F3: int | G3: HiddenRange | H3: DishRotation
B4: cookie | C4: cookie | E4: 120 | F4: 2 | G4: 5,15 | H4: Deg0
B5: macaron | C5: macaron | E5: 120 | F5: 2 | G5: 4,12 | H5: Deg0
B6: pudding | C6: pudding | E6: 120 | F6: 5 | G6: 15,45 | H6: Deg0
B7: puff | C7: puff | E7: 120 | F7: 2 | G7: 4,12 | H7: Deg0
B8: eggtart | C8: eggtart | E8: 120 | F8: 2 | G8: 3,9 | H8: Deg0
B9: mochi | C9: mochi | E9: 90 | F9: 2 | G9: 5,15 | H9: Deg0
B10: daifuku | C10: daifuku | E10: 120 | F10: 2 | G10: 3,9 | H10: Deg0
B11: choco_candy | C11: choco_candy | E11: 90 | F11: 2 | G11: 5,15 | H11: Deg0
B12: jelly | C12: jelly | E12: 120 | F12: 2 | G12: 2,7 | H12: Deg0
B13: cream_cell | C13: cream_cell | E13: 120 | F13: 2 | G13: 5,15 | H13: Deg0
B14: sugarbean | C14: sugarbean | E14: 60 | F14: 2 | G14: 5,15 | H14: Deg0
B15: gold_choco | C15: gold_choco | E15: 90 | F15: 2 | G15: 3,9 | H15: Deg0
... B50: double_cake | C50: double_cake | E50: 60 | F50: 23 | G50: 70,210 | H50: Deg0

Sheet skill
A1: ##var | B1: id | C1: termId | D1: subSkills
A2: ##comment | B2: 技能ID | C2: 关联术语ID(可空) | D2: 有序引用的子技能ID列表(| 分隔)
A3: ##type | B3: string | C3: string | D3: string
B4: sk_cookie | D4: ss_edge_multflat_v3
B5: sk_macaron | C5: term_sweet_transfer | D5: ss_flat_per_dish_adj_v8|ss_transfer_row_n1
B6: sk_pudding | D6: ss_flat_per_empty_adj_vm2
B7: sk_puff | D7: ss_layer_per_dish_adj_v2
B8: sk_eggtart | D8: ss_flat_per_run_v6
B9: sk_mochi | D9: ss_multflat_per_dish_col_v1
B10: sk_daifuku | D10: ss_flat_per_dish_row_v10
B11: sk_choco_candy | D11: ss_permflat_per_tag_v5
B12: sk_jelly | D12: ss_multflat_per_dish_all_adj_v0p2
B13: sk_cream_cell | D13: ss_layer_add_v5
B14: sk_sugarbean | C14: term_sweet_transfer | D14: ss_extra_settle_v1|ss_transfer_all_n1
B15: sk_gold_choco | D15: ss_grant_gold_filled_adj_v30
B16: sk_milk_slice | D16: ss_layer_filled_row_v10
B17: sk_sundae | D17: ss_multflat_per_dish_row_v2|ss_count_as_base_v1
B18: sk_cone | D18: ss_layer_add_v10|ss_temp_copy_v1
B19: sk_lollipop | C19: term_sweet_transfer | D19: ss_shape_mult_adj_v1p5|ss_transfer_col_n2
B20: sk_gummy | C20: term_sweet_transfer | D20: ss_mult_per_dish_adj_v1p2|ss_transfer_adj_n2
B21: sk_cupcake | D21: ss_copy_skill_adj_v1|ss_layer_per_tag_v6
B22: sk_mousse | D22: ss_mult_v1p5|ss_extra_settle_v1
B23: sk_toffee | C23: term_sweet_transfer | D23: ss_perm_flat_v10|ss_transfer_all_n2
B24: sk_nougat | C24: term_sweet_transfer | D24: ss_extra_settle_v1|ss_transfer_adj_n2
B25: sk_eggroll | D25: ss_multflat_per_dish_all_v0p2|ss_count_as_base_v3
B26: sk_choco_bar | C26: term_sweet_transfer | D26: ss_multflat_adj_v5|ss_transfer_all_n3
B27: sk_eclair | D27: ss_consume_layer_v10|ss_multflat_v5
B28: sk_tanghulu | C28: term_sweet_transfer | D28: ss_multflat_col_v3|ss_transfer_row_n3
B29: sk_souffle | D29: ss_layer_mult_v1p5
B30: sk_taosu | D30: ss_mult_tier_dishcount_row_row
B31: sk_mooncake | D31: ss_copy_skill_adj_v1|ss_count_as_base_v4
B32: sk_waffle | D32: ss_mult_v3|ss_count_as_filled_row_v9
B33: sk_dorayaki | D33: ss_count_as_col_v2|ss_multflat_v4
B34: sk_cream_cake | D34: ss_perm_flat_v10|ss_flat_category_cat_v10
B35: sk_donut | D35: ss_layer_add_v15|ss_multflat_v5
B36: sk_pengtang | C36: term_sweet_transfer | D36: ss_multflat_per_tag_v5|ss_transfer_col
B37: sk_parfait | D37: ss_mult_per_dish_adj_v1p2|ss_count_as_base_v9
B38: sk_sundae_big | D38: ss_mult_col_v2|ss_count_as_base_v4
B39: sk_swiss_roll | D39: ss_layer_add_v20|ss_multflat_all_v0p5
B40: sk_mango_sago | D40: ss_copy_skill_adj_v2|ss_count_as_base_v7
...

Sheet flavor
A1: ##var | B1: id | C1: name | D1: desc | E1: effectType | F1: effectValue | G1: effectParam | H1: termId
A2: ##comment | B2: 标签ID | C2: 标签名称 | D2: 标签描述 | E2: 效果类型 | F2: 效果数值 | G2: 效果参数 | H2: 关联术语ID
A3: ##type | B3: string | C3: string | D3: string | E3: TagEffectType | F3: list,float | G3: list,string | H3: string
B4: t_feast | C4: 盛宴 | D4: 棋盘上每有一道菜，本菜品分数 ×1.1。 | E4: PerDishOnBoard | F4: 0.1
B5: t_golden | C5: 黄金 | D5: 本菜品贡献的分数 ×{0}。 | E5: AddMult | F5: 2

Sheet cake_layer_buff
A1: ##var | B1: id | C1: order | D1: threshold | E1: category | F1: effectType | G1: valuePerLayer | H1: desc
A2: ##comment | B2: 档位ID | C2: 执行顺序 | D2: 层数阈值(>=生效) | E2: 作用分类 | F2: 效果类型(SkillActionType) | G2: 每层系数 | H2: 描述
A3: ##type | B3: string | C3: int | D3: int | E3: string | F3: SkillActionType | G3: float | H3: string
B4: clb_flat | C4: 0 | D4: 1 | E4: cake | F4: AddFlat | G4: 5 | H4: 欢乐蛋糕≥1层：所有蛋糕基础分 +5×层数。
B5: clb_multflat | C5: 1 | D5: 50 | E5: cake | F5: AddMultFlat | G5: 0.1 | H5: 欢乐蛋糕≥50层：所有蛋糕倍率 +0.1×层数。
B6: clb_mult | C6: 2 | D6: 100 | E6: cake | F6: AddMult | G6: 0.02 | H6: 欢乐蛋糕≥100层：所有蛋糕倍率 ×(0.02×层数)。

Sheet sub_skill
A1: ##var | B1: id | C1: trigger | D1: condType | E1: condScope | F1: condUnit | G1: condMode | H1: condParam | I1: actionType | J1: actionScope | K1: actionCount | L1: actionValue | M1: actionParam | N1: isPassive | O1: signed | P1: descTemplate
A2: ##comment | B2: 子技能ID(主键) | C2: 触发时机 | D2: 前提类型 | E2: 前提作用域 | F2: 计数单位 | G2: 计数模式 | H2: 前提附加参数 | I2: 行为类型 | J2: 行为作用域 | K2: 随机目标数(0=全部) | L2: 行为数值 | M2: 行为参数 | N2: 是否被动 | O2: 数值正负号 | P2: 占位符描述模板
A3: ##type | B3: string | C3: SkillTrigger | D3: SkillConditionType | E3: SkillScope | F3: CountUnit | G3: CountMode | H3: string | I3: SkillActionType | J3: SkillScope | K3: int | L3: list,float | M3: list,string | N3: bool | O3: bool | P3: string
B4: ss_edge_multflat_v3 | C4: OnSettle | D4: Edge | E4: Self | F4: Instances | G4: Gate | I4: AddMultFlat | J4: Self | K4: 0 | L4: 3 | N4: false | O4: true | P4: 处在棋盘边缘时，{ascopes}倍率 {0}。
B5: ss_flat_per_dish_adj_v8 | C5: OnSettle | D5: DishCount | E5: Round | F5: Kinds | G5: Per | I5: AddFlat | J5: Self | K5: 0 | L5: 8 | N5: false | O5: true | P5: {cscope}每有 1 {unit}食物，{ascopes}分数 {0}。
B6: ss_transfer_row_n1 | C6: OnSettle | D6: None | E6: Self | F6: Instances | G6: Per | I6: TransferSkills | J6: Row | K6: 1 | L6: 0 | N6: false | O6: false | P6: 甜蜜传递至{ascopes}食物
B7: ss_flat_per_empty_adj_vm2 | C7: OnSettle | D7: EmptyCell | E7: Round | F7: Instances | G7: Per | I7: AddFlat | J7: Self | K7: 0 | L7: -2 | N7: false | O7: true | P7: {cscope}每有 1 个空格，{ascopes}分数 {0}。
B8: ss_layer_per_dish_adj_v2 | C8: OnSettle | D8: DishCount | E8: Round | F8: Instances | G8: Per | I8: AddLayer | J8: Cake | K8: 0 | L8: 2 | N8: false | O8: true | P8: {cscope}每有 1 {unit}食物，欢乐蛋糕 {0} 层。
B9: ss_flat_per_run_v6 | C9: OnSettle | D9: SameKindInRun | E9: Self | F9: Instances | G9: Per | I9: PermanentAddFlat | J9: Self | K9: 0 | L9: 6 | N9: false | O9: true | P9: 结算时，{ascopes}分数永久 {0}。
B10: ss_multflat_per_dish_col_v1 | C10: OnSettle | D10: DishCount | E10: ColumnAndSelf | F10: Instances | G10: Per | I10: AddMultFlat | J10: Self | K10: 0 | L10: 1 | N10: false | O10: true | P10: {cscope}每有 1 {unit}食物，{ascopes}倍率 {0}。
B11: ss_flat_per_dish_row_v10 | C11: OnSettle | D11: DishCount | E11: RowAndSelf | F11: Instances | G11: Per | I11: AddFlat | J11: Self | K11: 0 | L11: 10 | N11: false | O11: true | P11: {cscope}每有 1 {unit}食物，{ascopes}分数 {0}。
B12: ss_permflat_per_tag_v5 | C12: OnSettle | D12: TagCount | E12: Self | F12: Instances | G12: Per | I12: PermanentAddFlat | J12: Self | K12: 0 | L12: 5 | N12: false | O12: true | P12: 结算每有1个技能，{ascopes}分数永久 {0}。
B13: ss_multflat_per_dish_all_adj_v0p2 | C13: OnSettle | D13: DishCount | E13: RowAndSelf | F13: Kinds | G13: Per | I13: AddMultFlat | J13: RoundAndSelf | K13: 0 | L13: 0.2 | N13: false | O13: true | P13: {cscope}每有 1 {unit}食物，{ascopes}倍率 {0}。
B14: ss_layer_add_v5 | C14: OnSettle | D14: None | E14: Self | F14: Instances | G14: Per | I14: AddLayer | J14: Cake | K14: 0 | L14: 5 | N14: false | O14: true | P14: 欢乐蛋糕 {0} 层。
B15: ss_extra_settle_v1 | C15: OnSettle | D15: None | E15: Self | F15: Instances | G15: Per | I15: ExtraSettlement | J15: Self | K15: 0 | L15: 1 | N15: true | O15: false | P15: 技能额外结算 {0} 次。 | R15: 设计比较危险
B16: ss_transfer_all_n1 | C16: OnSettle | D16: None | E16: Self | F16: Instances | G16: Per | I16: TransferSkills | J16: Other | K16: 1 | L16: 0 | N16: false | O16: false | P16: 甜蜜传递至{ascopes}食物
B17: ss_grant_gold_filled_adj_v30 | C17: OnSettle | D17: PositionFilled | E17: Round | F17: Instances | G17: Gate | I17: GrantGold | J17: Self | K17: 0 | L17: 30 | N17: false | O17: false | P17: 若{cscope}被填满，获得 {0} 金币。 | R17: 运营向的比较少
B18: ss_layer_filled_row_v10 | C18: OnSettle | D18: PositionFilled | E18: RowAndSelf | F18: Instances | G18: Gate | I18: AddLayer | J18: Cake | K18: 0 | L18: 10 | N18: false | O18: true | P18: 若{cscope}被填满，欢乐蛋糕 {0} 层。
B19: ss_multflat_per_dish_row_v2 | C19: OnSettle | D19: DishCount | E19: RowAndSelf | F19: Instances | G19: Per | I19: AddMultFlat | J19: Self | K19: 0 | L19: 2 | N19: false | O19: true | P19: {cscope}每有 1 {unit}食物，{ascopes}倍率 {0}。
B20: ss_count_as_base_v1 | C20: OnSettle | D20: None | E20: Self | F20: Instances | G20: Per | I20: AddCountAs | J20: Self | K20: 0 | L20: 1 | N20: true | O20: false | P20: {ascopes}视为 {countas} 个食物。
B21: ss_layer_add_v10 | C21: OnSettle | D21: None | E21: Self | F21: Instances | G21: Per | I21: AddLayer | J21: Cake | K21: 0 | L21: 10 | N21: false | O21: true | P21: 欢乐蛋糕 {0} 层。
B22: ss_temp_copy_v1 | C22: OnServe | D22: None | E22: Self | F22: Instances | G22: Per | I22: TempCopyDish | J22: Self | K22: 0 | L22: 1 | N22: false | O22: false | P22: 复制本菜品至空格中。 | R22: 需要立即结算
B23: ss_shape_mult_adj_v1p5 | C23: OnSettle | D23: ShapeMatch | E23: Round | F23: Instances | G23: Gate | H23: 1x1 | I23: AddMult | J23: Self | K23: 0 | L23: 1.5 | N23: false | O23: false | P23: {cscope}有占 1 格的食物时，{ascopes}倍率 ×{0}。
B24: ss_transfer_col_n2 | C24: OnSettle | D24: None | E24: Self | F24: Instances | G24: Per | I24: TransferSkills | J24: Column | K24: 2 | L24: 0 | N24: false | O24: false | P24: 甜蜜传递至{ascopes}食物
B25: ss_mult_per_dish_adj_v1p2 | C25: OnSettle | D25: DishCount | E25: Round | F25: Instances | G25: Per | I25: AddMult | J25: Self | K25: 0 | L25: 1.2 | N25: false | O25: false | P25: {cscope}每有 1 {unit}食物，{ascopes}倍率 ×{0}。
B26: ss_transfer_adj_n2 | C26: OnSettle | D26: None | E26: Self | F26: Instances | G26: Per | I26: TransferSkills | J26: Round | K26: 2 | L26: 0 | N26: false | O26: false | P26: 甜蜜传递至{ascopes}食物
B27: ss_copy_skill_adj_v1 | C27: OnSettle | D27: None | E27: Self | F27: Instances | G27: Per | I27: CopySkill | J27: Round | K27: 0 | L27: 1 | N27: false | O27: false | P27: 复制{ascope}食物的 {0} 个技能。
B28: ss_layer_per_tag_v6 | C28: OnSettle | D28: TagCount | E28: Self | F28: Instances | G28: Per | I28: AddLayer | J28: Cake | K28: 0 | L28: 6 | N28: false | O28: true | P28: 每有 1 个技能，欢乐蛋糕 {0} 层。
B29: ss_mult_v1p5 | C29: OnSettle | D29: None | E29: Self | F29: Instances | G29: Per | I29: AddMult | J29: Self | K29: 0 | L29: 1.5 | N29: false | O29: false | P29: {ascopes}倍率 ×{0}。
B30: ss_perm_flat_v10 | C30: OnSettle | D30: None | E30: Self | F30: Instances | G30: Per | I30: PermanentAddFlat | J30: Self | K30: 0 | L30: 10 | N30: false | O30: true | P30: {ascopes}分数永久 {0}。
B31: ss_transfer_all_n2 | C31: OnSettle | D31: None | E31: Self | F31: Instances | G31: Per | I31: TransferSkills | J31: Other | K31: 2 | L31: 0 | N31: false | O31: false | P31: 甜蜜传递至{ascopes}食物
B32: ss_multflat_per_dish_all_v0p2 | C32: OnSettle | D32: DishCount | E32: All | F32: Instances | G32: Per | I32: AddMultFlat | J32: Self | K32: 0 | L32: 0.2 | N32: false | O32: true | P32: {cscope}每有 1 {unit}食物，{ascopes}倍率 {0}。
B33: ss_count_as_base_v3 | C33: OnSettle | D33: None | E33: Self | F33: Instances | G33: Per | I33: AddCountAs | J33: Self | K33: 0 | L33: 3 | N33: true | O33: false | P33: {ascopes}视为 {countas} 个食物。
B34: ss_multflat_adj_v5 | C34: OnSettle | D34: None | E34: Self | F34: Instances | G34: Per | I34: AddMultFlat | J34: RoundAndSelf | K34: 0 | L34: 5 | N34: false | O34: true | P34: {ascopes}倍率 {0}。
B35: ss_transfer_all_n3 | C35: OnSettle | D35: None | E35: Self | F35: Instances | G35: Per | I35: TransferSkills | J35: Other | K35: 3 | L35: 0 | N35: false | O35: false | P35: 甜蜜传递至{ascopes}食物
... B39: ss_transfer_row_n3 | C39: OnSettle | D39: None | E39: Self | F39: Instances | G39: Per | I39: TransferSkills | J39: Row | K39: 3 | L39: 0 | N39: false | O39: false | P39: 甜蜜传递至{ascopes}食物
B40: ss_layer_mult_v1p5 | C40: OnSettle | D40: None | E40: Self | F40: Instances | G40: Per | I40: AddLayer | J40: Cake | K40: 0 | L40: 1.5 | M40: multfloor:5 | N40: false | O40: false | P40: 欢乐蛋糕 ×{0} 层，至少 +{floor} 层。
B41: ss_mult_tier_dishcount_row_row | C41: OnSettle | D41: DishCount | E41: RowAndSelf | F41: Instances | G41: Reach | H41: tiers:5|15|25 | I41: AddMult | J41: RowAndSelf | K41: 0 | L41: 0 | M41: tiervals:1.5|2.5|5 | N41: false | O41: false | P41: {cscope}食物达 {tiers} 个时，{ascopes}倍率 ×{tiervals}。
B42: ss_count_as_base_v4 | C42: OnSettle | D42: None | E42: Self | F42: Instances | G42: Per | I42: AddCountAs | J42: Self | K42: 0 | L42: 4 | N42: true | O42: false | P42: {ascopes}视为 {countas} 个食物。
B43: ss_mult_v3 | C43: OnSettle | D43: None | E43: Self | F43: Instances | G43: Per | I43: AddMult | J43: Self | K43: 0 | L43: 3 | N43: false | O43: false | P43: {ascopes}倍率 ×{0}。
...

Sheet 食物设计
A2: id | B2: 菜品 | C2: 形状 | D2: 美味度 | E2: 技能 | F2: 作用范围 | G2: 作用乘区 | H2: （前期/中期/后期） | I2: 所属build | J2: 备注 | M2: 技能列举
A3: 1 | B3: 曲奇 | C3: X | D3: 10 | E3: 处在边缘时，倍率+3 | G3: 加倍率 | H3: 前 | I3: 小而多 | M3: 行为 | O3: 甜蜜传递：使目标食物获得并结算此技能
A4: 2 | B4: 马卡龙 | C4: X | D4: 8 | E4: 周围每有一种食物，分数+8。甜蜜传递至同行1个食物 | G4: 分数 | H4: 前 | I4: 传递 | M4: 前提+行为
A5: 3 | B5: 布丁 | C5: X | D5: 30 | E5: 周围每有1个空格，分数-2 | G5: 分数 | H5: 前 | I5: 小而多 | K5: 本食物默认不写 | M5: 行为+行为
A6: 4 | B6: 泡芙 | C6: X | D6: 8 | E6: 周围每有1个食物，蛋糕+2层 | G6: buff | H6: 前 | I6: 多辅一 | M6: 前提+行为+行为
A7: 5 | B7: 蛋挞 | C7: X | D7: 6 | E7: 结算时，分数永久+6 | G7: 分数 | H7: 前 | I7: 小而多 | M7: 行为+行为+行为
A8: 6 | B8: 麻薯 | C8: X | D8: 10 | E8: 同列每有1个食物，倍率+1 | G8: 乘倍率 | H8: 前中 | I8: 小而多
A9: 7 | B9: 大福 | C9: X | D9: 6 | E9: 同行每有一个食物，分数+10 | G9: 分数 | H9: 前 | I9: 小而多
A10: 8 | B10: 巧克力糖 | C10: X | D10: 10 | E10: 每有1个技能，分数永久+5 | G10: 永久加分数 | H10: 前中 | I10: 传递 | N10: 前提
A11: 9 | B11: 果冻 | C11: X | D11: 4 | E11: 同列每有1种食物，周围食物倍率+0.2 | G11: 加倍率 | H11: 前 | I11: 小而多
A12: 10 | B12: 奶油小格 | C12: X | D12: 10 | E12: 蛋糕+5层 | G12: buff | H12: 前 | I12: 多辅一 | M12: 类别 | N12: 技能机制 | O12: 技能详情
A13: 11 | B13: 糖豆 | C13: X | D13: 10 | E13: 技能额外结算1次。甜蜜传递至1个食物 | G13: 结算 | H13: 前中后 | I13: 传递 | M13: 空间 | N13: 位置检测 | O13: 如果（同行/同列/周围/全部）被填满
A14: 12 | B14: 金巧克力 | C14: X | D14: 6 | E14: 如果周围被填满，获得30个金币 | G14: 金币 | H14: 前中 | I14: 通用 | N14: 空格检测 | O14: （周围/同列/同行/空）每有1个空格
A15: 13 | B15: 奶片 | C15: X | D15: 8 | E15: 如果同行被填满，蛋糕+10层 | G15: buff | H15: 前中 | I15: 多辅一 | N15: 边缘检测 | O15: 若本食物处在边缘
A16: 14 | B16: 圣代 | C16: XX | D16: 20 | E16: 视为2个食物，同行每有1个食物，倍率+2 | G16: 加倍率 | H16: 中 | I16: 小而多 | M16: 数量 | N16: 检测数量 | O16: （周围/同列/同行/空）每有1（种/个）食物
A17: 15 | B17: 甜筒 | C17: X | D17: 20 | E17: 蛋糕+10层，临时复制本菜品至空格中 | G17: buff | H17: 中 | I17: 多辅一 | N17: 阶梯数量 | O17: （周围/同列/同行/空）食物数量达到[2/5/10]时
C18: X | N18: 大小检测 | O18: （周围/同列/同行/空）每有1（种/个）（大于等于/小于等于）3格的食物
A19: 16 | B19: 棒棒糖 | C19: XX | D19: 10 | E19: 周围占1格的食物时，倍率x1.5。甜蜜传递至同列2个食物 | G19: 乘倍率 | H19: 中 | I19: 传递 | N19: 顺序检测 | O19: （前面/后面）每有1个食物
A20: 17 | B20: 软糖 | C20: XX | E20: 周围每有1个食物，倍率x1.2。甜蜜传递至周围2个食物 | G20: 乘倍率 | H20: 中 | I20: 传递 | M20: 种类 | N20: 空间相同检测 | O20: （周围/同列/同行/空）每有1（种/个）相同的食物
A21: 18 | B21: 杯子蛋糕 | C21: XX | D21: 14 | E21: 获得周围食物的1个技能。自身每有1个技能，使蛋糕+6层 | G21: buff | H21: 中后 | I21: 多辅一 | N21: 大局相同检测 | O21: 本局每结算过一次本种菜品
A22: 19 | B22: 慕斯蛋糕 | C22: X | D22: 16 | E22: 倍率x1.5。技能额外结算1次 | G22: 乘倍率 | H22: 中后 | I22: 多辅一 | N22: 小局相同检测 | O22: 本次美食品鉴，每（结算过一次/有一个）本种菜品
C23: X | M23: 标签 | N23: 标签检测 | O23: 本食物每有1（种/个）技能
A24: 20 | B24: 太妃糖 | C24: X | D24: 15 | E24: 分数永久+10。甜蜜传递至2个食物 | G24: 永久乘分数 | H24: 中 | I24: 传递 | M24: 形状 | N24: 形状检测 | O24: （周围/同列/同行/空）每有1（种/个）1*1的食物
C25: X | N25: 形状检测 | O25: 若（周围/全部）存在xx形状的空格
A26: 21 | B26: 牛轧糖 | C26: X | D26: 20 | E26: 技能额外结算1次。甜蜜传递至2个周围食物 | G26: 结算 | H26: 中 | I26: 传递 | M26: 上菜 | N26: 上菜时检测 | O26: 上菜时，（同行/同列/周围/全部）每有1（种/个）食物
C27: X | N27: 上菜检测 | O27: 上菜时
A28: 22 | B28: 蛋卷 | C28: XXX | D28: 30 | E28: 视为4个食物，每有1个食物，倍率+0.2 | G28: 加倍率 | H28: 中 | I28: 小而多 | M28: 菜谱 | N28: 菜谱检测 | O28: 菜谱中食物（大于等于/小于等于）3（种/个）时
A29: 23 | B29: 巧克力棒 | C29: XXX | D29: 40 | E29: 周围食物倍率+5。甜蜜传递至3个食物 | G29: 倍率 | H29: 中 | I29: 传递 | N29: 特定种类检测 | O29: 带有“蛋糕”的食物数量达到4（种/个）时
A30: 24 | B30: 闪电泡芙 | C30: X | D30: 30 | E30: 消耗10层欢乐蛋糕，倍率+5 | G30: 结算 | H30: 中 | I30: 多辅一 | M30: 传递 | N30: 传递检测 | O30: 本食物每有1个被传递的技能
C31: X | N31: 传递检测 | O31: 本食物有被传递的技能时
C32: X | N32: 传递次数检测 | O32: 本局传递次数达到10次时
A33: 25 | B33: 糖葫芦 | C33: X | D33: 20 | E33: 同列食物倍率+3。甜蜜传递至同行3个食物 | G33: 加倍率 | H33: 中 | I33: 传递 | M33: 蛋糕 | N33: 层数检测 | O33: 欢乐蛋糕层数小于等于10层时
C34: X | M34: 状态 | N34: 特殊状态检测 | O34: （周围/同列/同行/空）有n个（失效/消耗）的食物时
C35: X
A36: 26 | B36: 舒芙蕾 | C36: XX | D36: 30 | E36: 蛋糕x1.5层，至少+5层 | G36: buff | H36: 中 | I36: 多辅一
C37: XX | N37: 类别 | O37: 技能详情
A38: 27 | B38: 桃酥 | C38: XX | D38: 20 | E38: 同行食物达「5/15/25」个时，同行食物倍率x「1.5/2.5/5」 | G38: 乘倍率 | H38: 中后 | I38: 小而多 | N38: 层数消耗 | O38: 消耗（5层/所有）欢乐蛋糕层数
C39: XX | N39: 层数转化分数 | O39: 每10层使（周围/同列/同行/空/下一个结算）（全部/随机两个）食物分数（x1.5/+10）
A40: 28 | B40: 月饼 | C40: XX | D40: 25 | E40: 视为5个食物，复制周围食物的1个技能 | G40: 技能 | H40: 中后 | I40: 小而多 | N40: 层数转化结算 | O40: 每10层使（周围/同列/同行/空/下一个结算）（全部/随机两个）食物额外结算1次
C41: XX | N41: 层数增加 | O41: 欢乐蛋糕层数（x1.5/+10）
...

Sheet 定义
M4: 同列 | N4: 同列 | O4: 同列 | P4: 同列
M5: 同列 | N5: 同列 | O5: 周围/同列 | P5: 周围/同列 | Q5: 周围
J6: 同行 | K6: 同行 | L6: 同行 | M6: 同行/同列 | N6: 同行/同列 | O6: 周围/同行/同列 | Q6: 周围/同行 | R6: 同行
J7: 同行 | K7: 同行 | L7: 同行/周围 | M7: 周围/同行/同列 | N7: 周围/同行/同列 | O7: 周围/同行/同列 | Q7: 周围/同行 | R7: 同行
H8: 同行 | I8: 同行 | J8: 同行 | K8: 同行 | L8: 周围/同行 | Q8: 周围/同行 | R8: 同行
L9: 周围 | M9: 周围/同列 | N9: 周围/同列 | O9: 周围/同列 | P9: 周围/同列 | Q9: 周围
M10: 同列 | N10: 同列 | O10: 同列 | P10: 同列
M11: 同列 | N11: 同列
M12: 同列 | N12: 同列
